Workbook
Name _18_11_2023: Dmart_sales!$J$2:$J$15345
Name _19_11_2023: Dmart_sales!$K$2:$K$15345
Name Bangalore: Dmart_sales!$B$4:$N$4
Name Card: Dmart_sales!$M$2:$M$15345
Name category: Dmart_sales!$C$2:$C$15346
Name city: Dmart_sales!$O$2:$O$15346
Name customer_type: Dmart_sales!$L$2:$L$15346
Name Delhi: Dmart_sales!$B$10:$N$10
Name delivery_date: Dmart_sales!$K$2:$K$15346
Name discount: Dmart_sales!$F$2:$F$15346
Name discount_am: Dmart_sales!$F$1:$F$15346
Name discount_value: Dmart_sales!$G$2:$G$15346
Name Grocery: Dmart_sales!$C$2:$C$15345
Name Hyderabad: Dmart_sales!$B$3:$N$3
Name Mumbai: Dmart_sales!$B$7:$N$7
Name Net_Revenue: Dmart_sales!$H$2:$H$15346
Name New: Dmart_sales!$L$2:$L$15345
Name ORD100000_: Dmart_sales!$B$2:$N$2
Name ORD100001_: Dmart_sales!$B$3:$N$3
Name ORD100002_: Dmart_sales!$B$4:$N$4
Name ORD100003_: Dmart_sales!$B$5:$N$5
Name ORD100004_: Dmart_sales!$B$6:$N$6
Name ORD100005_: Dmart_sales!$B$7:$N$7
Name ORD100006_: Dmart_sales!$B$8:$N$8
Name ORD100007_: Dmart_sales!$B$9:$N$9
Name ORD100008_: Dmart_sales!$B$10:$N$10
Name ORD100009_: Dmart_sales!$B$11:$N$11
Name ORD100010_: Dmart_sales!$B$12:$N$12
Name ORD100011_: Dmart_sales!$B$13:$N$13
Name ORD100012_: Dmart_sales!$B$14:$N$14
Name ORD100013_: Dmart_sales!$B$15:$N$15
Name ORD100014_: Dmart_sales!$B$16:$N$16
Name ORD100015_: Dmart_sales!$B$17:$N$17
Name ORD100016_: Dmart_sales!$B$18:$N$18
Name ORD100017_: Dmart_sales!$B$19:$N$19
Name ORD100018_: Dmart_sales!$B$20:$N$20
Name ORD100019_: Dmart_sales!$B$21:$N$21
Name ORD100020_: Dmart_sales!$B$22:$N$22
Name ORD100021_: Dmart_sales!$B$23:$N$23
Name ORD100022_: Dmart_sales!$B$24:$N$24
Name ORD100023_: Dmart_sales!$B$25:$N$25
Name ORD100024_: Dmart_sales!$B$26:$N$26
Name ORD100025_: Dmart_sales!$B$27:$N$27
Name ORD100026_: Dmart_sales!$B$28:$N$28
Name ORD100027_: Dmart_sales!$B$29:$N$29
Name ORD100028_: Dmart_sales!$B$30:$N$30
Name ORD100029_: Dmart_sales!$B$31:$N$31
Name ORD100030_: Dmart_sales!$B$32:$N$32
Name ORD100031_: Dmart_sales!$B$33:$N$33
Name ORD100032_: Dmart_sales!$B$34:$N$34
Name ORD100033_: Dmart_sales!$B$35:$N$35
Name ORD100034_: Dmart_sales!$B$36:$N$36
Name ORD100035_: Dmart_sales!$B$37:$N$37
Name ORD100036_: Dmart_sales!$B$38:$N$38
Name ORD100037_: Dmart_sales!$B$39:$N$39
Name ORD100038_: Dmart_sales!$B$40:$N$40
Name ORD100039_: Dmart_sales!$B$41:$N$41
Name ORD100040_: Dmart_sales!$B$42:$N$42
Name ORD100041_: Dmart_sales!$B$43:$N$43
Name ORD100042_: Dmart_sales!$B$44:$N$44

Sheet Dmart_sales
A1: order_id | B1: region | C1: category | D1: sales | E1: sales category | F1: discount | G1: discount value | H1: Net Revenue | I1: quantity | J1: order_date | K1: delivery_date | L1: customer_type | M1: payment_mode | N1: profit | O1: city | P1: column 1 | Q1: error | R1: error_corr
A2: ORD100000 | B2: East | C2: Clothing | D2: 713.49 | E2: =IF(D2>4000,"High sales"," Low sales") -> Low sales | F2: 0.31 | G2: =D2*F2 -> 221.1819 | H2: =D2-G2 -> 492.3081 | I2: 3 | J2: 45015 | K2: 45017 | L2: Member | M2: UPI | N2: 114.72 | O2: Pune | P2: =IF(AND(H2>5000,N2>500),"good","not good") -> not good
A3: ORD100001 | B3: West | C3: Electronics | D3: 3802.97 | E3: =IF(D3>4000,"High sales"," Low sales") -> Low sales | F3: 0.38 | G3: =D3*F3 -> 1445.1286 | H3: =D3-G3 -> 2357.8414 | I3: 4 | J3: 45166 | K3: 45172 | L3: Regular | M3: Card | N3: 971.41 | O3: Hyderabad | P3: =IF(AND(H3>5000,N3>500),"good","not good") -> not good
A4: ORD100002 | B4: North | C4: Home Care | D4: 3588.97 | E4: =IF(D4>4000,"High sales"," Low sales") -> Low sales | F4: 0.1 | G4: =D4*F4 -> 358.897 | H4: =D4-G4 -> 3230.073 | I4: 7 | J4: 45360 | K4: 45366 | L4: Regular | M4: Cash | N4: 769.08 | O4: Bangalore | P4: =IF(AND(H4>5000,N4>500),"good","not good") -> not good
A5: ORD100003 | B5: East | C5: Electronics | D5: 1160.86 | E5: =IF(D5>4000,"High sales"," Low sales") -> Low sales | F5: 0.27 | G5: =D5*F5 -> 313.4322 | H5: =D5-G5 -> 847.4278 | I5: 5 | J5: 45578 | K5: 45584 | L5: Member | M5: UPI | N5: 71.61 | O5: Pune | P5: =IF(AND(H5>5000,N5>500),"good","not good") -> not good
A6: ORD100004 | B6: East | C6: Electronics | D6: 3071.32 | E6: =IF(D6>4000,"High sales"," Low sales") -> Low sales | F6: 0 | G6: =D6*F6 -> 0 | H6: =D6-G6 -> 3071.32 | I6: 7 | J6: 45022 | K6: 45025 | L6: New | M6: Cash | N6: 621.92 | O6: Bangalore | P6: =IF(AND(H6>5000,N6>500),"good","not good") -> not good | W6: PERSON A | X6: Person A
A7: ORD100005 | B7: West | C7: Grocery | D7: 2566.18 | E7: =IF(D7>4000,"High sales"," Low sales") -> Low sales | F7: 0.02 | G7: =D7*F7 -> 51.3236 | H7: =D7-G7 -> 2514.8564 | I7: 6 | J7: 45108 | K7: 45111 | L7: Member | M7: UPI | N7: 578.94 | O7: Mumbai | P7: =IF(AND(H7>5000,N7>500),"good","not good") -> not good | W7: PERSON B | X7: Person B
A8: ORD100006 | B8: North | C8: Personal Care | D8: 398 | E8: =IF(D8>4000,"High sales"," Low sales") -> Low sales | F8: 0.16 | G8: =D8*F8 -> 63.68 | H8: =D8-G8 -> 334.32 | I8: 4 | J8: 45119 | K8: 45124 | L8: New | M8: Cash | N8: 110.31 | O8: Mumbai | P8: =IF(AND(H8>5000,N8>500),"good","not good") -> not good | W8: PERSON A | X8: Person A
A9: ORD100007 | B9: North | C9: Personal Care | D9: 1462.95 | E9: =IF(D9>4000,"High sales"," Low sales") -> Low sales | F9: 0.23 | G9: =D9*F9 -> 336.4785 | H9: =D9-G9 -> 1126.4715 | I9: 2 | J9: 45064 | K9: 45066 | L9: Regular | M9: UPI | N9: 91.68 | O9: Bangalore | P9: =IF(AND(H9>5000,N9>500),"good","not good") -> not good | W9: PERSON B | X9: Person B
A10: ORD100008 | B10: East | C10: Personal Care | D10: 4997.47 | E10: =IF(D10>4000,"High sales"," Low sales") -> High sales | F10: 0.29 | G10: =D10*F10 -> 1449.2663 | H10: =D10-G10 -> 3548.2037 | I10: 6 | J10: 45296 | K10: 45299 | L10: Regular | M10: Card | N10: 995.78 | O10: Delhi | P10: =IF(AND(H10>5000,N10>500),"good","not good") -> not good | W10: PERSON A | X10: Person A
A11: ORD100009 | B11: South | C11: Grocery | D11: 587.72 | E11: =IF(D11>4000,"High sales"," Low sales") -> Low sales | F11: 0.44 | G11: =D11*F11 -> 258.5968 | H11: =D11-G11 -> 329.1232 | I11: 6 | J11: 45514 | K11: 45521 | L11: New | M11: Cash | N11: 102.96 | O11: Pune | P11: =IF(AND(H11>5000,N11>500),"good","not good") -> not good | W11: PERSON B | X11: Person B
A12: ORD100010 | B12: East | C12: Clothing | D12: 2581.42 | E12: =IF(D12>4000,"High sales"," Low sales") -> Low sales | F12: 0.39 | G12: =D12*F12 -> 1006.7538 | H12: =D12-G12 -> 1574.6662 | I12: 6 | J12: 45419 | K12: 45420 | L12: Regular | M12: Cash | N12: 542.82 | O12: Bangalore | P12: =IF(AND(H12>5000,N12>500),"good","not good") -> not good | W12: PERSON A | X12: Person A
A13: ORD100011 | B13: East | C13: Clothing | D13: 4261.74 | E13: =IF(D13>4000,"High sales"," Low sales") -> High sales | F13: 0.15 | G13: =D13*F13 -> 639.261 | H13: =D13-G13 -> 3622.479 | I13: 1 | J13: 45171 | K13: 45172 | L13: New | M13: UPI | N13: 1028.47 | O13: Pune | P13: =IF(AND(H13>5000,N13>500),"good","not good") -> not good | W13: PERSON B | X13: Person B
A14: ORD100012 | B14: East | C14: Home Care | D14: 1573.19 | E14: =IF(D14>4000,"High sales"," Low sales") -> Low sales | F14: 0.37 | G14: =D14*F14 -> 582.0803 | H14: =D14-G14 -> 991.1097 | I14: 6 | J14: 45331 | K14: 45338 | L14: New | M14: Cash | N14: 131.5 | O14: Bangalore | P14: =IF(AND(H14>5000,N14>500),"good","not good") -> not good | W14: PERSON A | X14: Person A
A15: ORD100013 | B15: East | C15: Clothing | D15: 1377.47 | E15: =IF(D15>4000,"High sales"," Low sales") -> Low sales | F15: 0.27 | G15: =D15*F15 -> 371.9169 | H15: =D15-G15 -> 1005.5531 | I15: 2 | J15: 45074 | K15: 45075 | L15: Member | M15: Cash | N15: 255.49 | O15: Delhi | P15: =IF(AND(H15>5000,N15>500),"good","not good") -> not good | W15: PERSON B | X15: Person B
A16: ORD100014 | B16: West | C16: Clothing | D16: 4464.89 | E16: =IF(D16>4000,"High sales"," Low sales") -> High sales | F16: 0.39 | G16: =D16*F16 -> 1741.3071 | H16: =D16-G16 -> 2723.5829 | I16: 5 | J16: 45296 | K16: 45303 | L16: Regular | M16: UPI | N16: 804.36 | O16: Pune | P16: =IF(AND(H16>5000,N16>500),"good","not good") -> not good | W16: PERSON A | X16: Person A
A17: ORD100015 | B17: North | C17: Personal Care | D17: 1593.67 | E17: =IF(D17>4000,"High sales"," Low sales") -> Low sales | F17: 0.21 | G17: =D17*F17 -> 334.6707 | H17: =D17-G17 -> 1258.9993 | I17: 7 | J17: 45583 | K17: 45587 | L17: Member | M17: Card | N17: 284.91 | O17: Chennai | P17: =IF(AND(H17>5000,N17>500),"good","not good") -> not good
A18: ORD100016 | B18: West | C18: Electronics | D18: 3292.32 | E18: =IF(D18>4000,"High sales"," Low sales") -> Low sales | F18: 0.05 | G18: =D18*F18 -> 164.616 | H18: =D18-G18 -> 3127.704 | I18: 1 | J18: 45042 | K18: 45043 | L18: Member | M18: Card | N18: 504.83 | O18: Mumbai | P18: =IF(AND(H18>5000,N18>500),"good","not good") -> not good
A19: ORD100017 | B19: West | C19: Clothing | D19: 3727.53 | E19: =IF(D19>4000,"High sales"," Low sales") -> Low sales | F19: 0.31 | G19: =D19*F19 -> 1155.5343 | H19: =D19-G19 -> 2571.9957 | I19: 5 | J19: 45228 | K19: 45235 | L19: Regular | M19: Card | N19: 978.07 | O19: Chennai | P19: =IF(AND(H19>5000,N19>500),"good","not good") -> not good | U19: 31 | V19: 1 | W19: 2 | X19: 3 | Y19: 4 | Z19: 5
A20: ORD100018 | B20: West | C20: Clothing | D20: 3964.23 | E20: =IF(D20>4000,"High sales"," Low sales") -> Low sales | F20: 0.28 | G20: =D20*F20 -> 1109.9844 | H20: =D20-G20 -> 2854.2456 | I20: 9 | J20: 45448 | K20: 45451 | L20: Member | M20: UPI | N20: 260.95 | O20: Bangalore | P20: =IF(AND(H20>5000,N20>500),"good","not good") -> not good | T20: a | U20: p | V20: p | W20: p | X20: p | Y20: a | Z20: p
A21: ORD100019 | B21: East | C21: Grocery | D21: 4974.32 | E21: =IF(D21>4000,"High sales"," Low sales") -> High sales | F21: 0.48 | G21: =D21*F21 -> 2387.6736 | H21: =D21-G21 -> 2586.6464 | I21: 3 | J21: 45047 | K21: 45051 | L21: Regular | M21: Card | N21: 727.29 | O21: Delhi | P21: =IF(AND(H21>5000,N21>500),"good","not good") -> not good | T21: b | U21: a | V21: a | W21: p | X21: p | Y21: a | Z21: p
A22: ORD100020 | B22: South | C22: Home Care | D22: 4035.64 | E22: =IF(D22>4000,"High sales"," Low sales") -> High sales | F22: 0.08 | G22: =D22*F22 -> 322.8512 | H22: =D22-G22 -> 3712.7888 | I22: 2 | J22: 45586 | K22: 45593 | L22: Regular | M22: Cash | N22: 798.81 | O22: Delhi | P22: =IF(AND(H22>5000,N22>500),"good","not good") -> not good | T22: c | U22: p | V22: p | W22: a | X22: p | Y22: p | Z22: a
A23: ORD100021 | B23: North | C23: Grocery | D23: 3319.36 | E23: =IF(D23>4000,"High sales"," Low sales") -> Low sales | F23: 0.33 | G23: =D23*F23 -> 1095.3888 | H23: =D23-G23 -> 2223.9712 | I23: 2 | J23: 45153 | K23: 45159 | L23: Member | M23: Cash | N23: 920.22 | O23: Bangalore | P23: =IF(AND(H23>5000,N23>500),"good","not good") -> not good | T23: d | U23: p | V23: p | W23: p | X23: p | Y23: p | Z23: p
A24: ORD100022 | B24: South | C24: Personal Care | D24: 4487.77 | E24: =IF(D24>4000,"High sales"," Low sales") -> High sales | F24: 0.24 | G24: =D24*F24 -> 1077.0648 | H24: =D24-G24 -> 3410.7052 | I24: 3 | J24: 45657 | K24: 45659 | L24: Regular | M24: Card | N24: 931.37 | O24: Pune | P24: =IF(AND(H24>5000,N24>500),"good","not good") -> not good | T24: e | U24: p | V24: a | W24: p | X24: a | Y24: p | Z24: p
A25: ORD100023 | B25: West | C25: Electronics | D25: 4538.15 | E25: =IF(D25>4000,"High sales"," Low sales") -> High sales | F25: 0.19 | G25: =D25*F25 -> 862.2485 | H25: =D25-G25 -> 3675.9015 | I25: 1 | J25: 45005 | K25: 45008 | L25: Regular | M25: Cash | N25: 375.7 | O25: Delhi | P25: =IF(AND(H25>5000,N25>500),"good","not good") -> not good | T25: f | U25: p | V25: p | W25: p | X25: a | Y25: p | Z25: a
A26: ORD100024 | B26: West | C26: Home Care | D26: 4868.52 | E26: =IF(D26>4000,"High sales"," Low sales") -> High sales | F26: 0.4 | G26: =D26*F26 -> 1947.408 | H26: =D26-G26 -> 2921.112 | I26: 2 | J26: 45272 | K26: 45273 | L26: Regular | M26: Cash | N26: 1072.26 | O26: Mumbai | P26: =IF(AND(H26>5000,N26>500),"good","not good") -> not good | T26: g | U26: p | V26: a | W26: p | X26: a | Y26: p | Z26: p
A27: ORD100025 | B27: South | C27: Grocery | D27: 3904.68 | E27: =IF(D27>4000,"High sales"," Low sales") -> Low sales | F27: 0.41 | G27: =D27*F27 -> 1600.9188 | H27: =D27-G27 -> 2303.7612 | I27: 6 | J27: 45066 | K27: 45072 | L27: Regular | M27: Card | N27: 526.66 | O27: Hyderabad | P27: =IF(AND(H27>5000,N27>500),"good","not good") -> not good
A28: ORD100026 | B28: South | C28: Clothing | D28: 1055.14 | E28: =IF(D28>4000,"High sales"," Low sales") -> Low sales | F28: 0.36 | G28: =D28*F28 -> 379.8504 | H28: =D28-G28 -> 675.2896 | I28: 8 | J28: 45462 | K28: 45468 | L28: Member | M28: UPI | N28: 207.61 | O28: Chennai | P28: =IF(AND(H28>5000,N28>500),"good","not good") -> not good
A29: ORD100027 | B29: South | C29: Clothing | D29: 3578.05 | E29: =IF(D29>4000,"High sales"," Low sales") -> Low sales | F29: 0.04 | G29: =D29*F29 -> 143.122 | H29: =D29-G29 -> 3434.928 | I29: 4 | J29: 45215 | K29: 45217 | L29: New | M29: Card | N29: 689.74 | O29: Mumbai | P29: =IF(AND(H29>5000,N29>500),"good","not good") -> not good
A30: ORD100028 | B30: West | C30: Home Care | D30: 468.13 | E30: =IF(D30>4000,"High sales"," Low sales") -> Low sales | F30: 0.17 | G30: =D30*F30 -> 79.5821 | H30: =D30-G30 -> 388.5479 | I30: 2 | J30: 45255 | K30: 45261 | L30: Member | M30: UPI | N30: 43.58 | O30: Hyderabad | P30: =IF(AND(H30>5000,N30>500),"good","not good") -> not good
A31: ORD100029 | B31: West | C31: Clothing | D31: 1658.02 | E31: =IF(D31>4000,"High sales"," Low sales") -> Low sales | F31: 0.02 | G31: =D31*F31 -> 33.1604 | H31: =D31-G31 -> 1624.8596 | I31: 5 | J31: 45356 | K31: 45357 | L31: New | M31: Cash | N31: 422.33 | O31: Delhi | P31: =IF(AND(H31>5000,N31>500),"good","not good") -> not good
A32: ORD100030 | B32: North | C32: Grocery | D32: 667.46 | E32: =IF(D32>4000,"High sales"," Low sales") -> Low sales | F32: 0.17 | G32: =D32*F32 -> 113.4682 | H32: =D32-G32 -> 553.9918 | I32: 3 | J32: 45026 | K32: 45031 | L32: New | M32: Card | N32: 123.49 | O32: Pune | P32: =IF(AND(H32>5000,N32>500),"good","not good") -> not good
A33: ORD100031 | B33: North | C33: Grocery | D33: 4754.72 | E33: =IF(D33>4000,"High sales"," Low sales") -> High sales | F33: 0.32 | G33: =D33*F33 -> 1521.5104 | H33: =D33-G33 -> 3233.2096 | I33: 5 | J33: 45527 | K33: 45531 | L33: New | M33: Cash | N33: 697.03 | O33: Chennai | P33: =IF(AND(H33>5000,N33>500),"good","not good") -> not good
A34: ORD100032 | B34: West | C34: Clothing | D34: 1759.9 | E34: =IF(D34>4000,"High sales"," Low sales") -> Low sales | F34: 0.26 | G34: =D34*F34 -> 457.574 | H34: =D34-G34 -> 1302.326 | I34: 3 | J34: 44933 | K34: 44939 | L34: Regular | M34: Cash | N34: 178.58 | O34: Delhi | P34: =IF(AND(H34>5000,N34>500),"good","not good") -> not good
A35: ORD100033 | B35: South | C35: Clothing | D35: 3594.76 | E35: =IF(D35>4000,"High sales"," Low sales") -> Low sales | F35: 0.35 | G35: =D35*F35 -> 1258.166 | H35: =D35-G35 -> 2336.594 | I35: 4 | J35: 45097 | K35: 45099 | L35: New | M35: UPI | N35: 1002.97 | O35: Delhi | P35: =IF(AND(H35>5000,N35>500),"good","not good") -> not good
A36: ORD100034 | B36: South | C36: Personal Care | D36: 2899.46 | E36: =IF(D36>4000,"High sales"," Low sales") -> Low sales | F36: 0.28 | G36: =D36*F36 -> 811.8488 | H36: =D36-G36 -> 2087.6112 | I36: 5 | J36: 45189 | K36: 45190 | L36: Regular | M36: Cash | N36: 320.43 | O36: Bangalore | P36: =IF(AND(H36>5000,N36>500),"good","not good") -> not good
A37: ORD100035 | B37: North | C37: Electronics | D37: 626.81 | E37: =IF(D37>4000,"High sales"," Low sales") -> Low sales | F37: 0.28 | G37: =D37*F37 -> 175.5068 | H37: =D37-G37 -> 451.3032 | I37: 7 | J37: 45298 | K37: 45303 | L37: Regular | M37: UPI | N37: 177.84 | O37: Mumbai | P37: =IF(AND(H37>5000,N37>500),"good","not good") -> not good
A38: ORD100036 | B38: West | C38: Home Care | D38: 2850.59 | E38: =IF(D38>4000,"High sales"," Low sales") -> Low sales | F38: 0.26 | G38: =D38*F38 -> 741.1534 | H38: =D38-G38 -> 2109.4366 | I38: 2 | J38: 45470 | K38: 45474 | L38: Regular | M38: Card | N38: 528.38 | O38: Chennai | P38: =IF(AND(H38>5000,N38>500),"good","not good") -> not good
... A15346: ORD115344 | B15346: South | C15346: Grocery | D15346: 4984.32 | E15346: =IF(D15346>4000,"High sales"," Low sales") -> High sales | F15346: 0.21 | G15346: =D15346*F15346 -> 1046.7072 | H15346: =D15346-G15346 -> 3937.6128 | I15346: 3 | J15346: 45248 | K15346: 45249 | L15346: New | M15346: Card | N15346: 909.1 | O15346: Bangalore | P15346: =IF(AND(H15346>5000,N15346>500),"good","not good") -> not good
D15347: =SUM(D2:D15346) -> 39262878
...

Sheet 3-8
B2: Marks | C2: Attendance | D2: Grade | E2: Result | F2: gen | G2: Exam | H2: Scholarship | I2: ifs | J2: gender | K2: Category | L2: Sales | M2: SALES_IF | N2: mark_switch
B3: 53 | C3: 90 | D3: {=IF(B3>90,"A",IF(B3>75,"B",IF(B3>50,"C",FAIL)))} -> C | E3: =IF(B3>=45,"PASS","FAIL") -> PASS | F3: m | G3: =AND(B3>50,C3>75) -> TRUE | H3: =IF(B3>95,"scholarship","not") -> not | I3: {=_xlfn.IFS(B3>90,"A",B3>80,"B",B3>60,"C",B3<60,"FAIL")} -> FAIL | J3: {=_xlfn.SWITCH(F3,"m","male","f","female","unknown")} -> male | K3: clothes | L3: 788 | M3: =IF(L3="",L19,L3) -> 788 | N3: {=_xlfn.SWITCH(TRUE,B3>=85,"A",B3>=75,"B",B3>=60,"C","FAIL")} -> FAIL
B4: 62 | C4: 95 | D4: {=IF(B4>90,"A",IF(B4>75,"B",IF(B4>50,"C",FAIL)))} -> C | E4: =IF(B4>=45,"PASS","FAIL") -> PASS | F4: f | G4: =AND(B4>50,C4>75) -> TRUE | H4: =IF(B4>95,"scholarship","not") -> not | I4: {=_xlfn.IFS(B4>90,"A",B4>80,"B",B4>60,"C",B4<60,"FAIL")} -> C | J4: {=_xlfn.SWITCH(F4,"m","male","f","female","unknown")} -> female | K4: furniture | L4: 514 | M4: =IF(L4="",L20,L4) -> 514 | N4: {=_xlfn.SWITCH(TRUE,B4>=85,"A",B4>=75,"B",B4>=60,"C","FAIL")} -> C
B5: 48 | C5: 67 | D5: =IF(B5>90,"A",IF(B5>75,"B",IF(B5>50,"C","FAIL"))) -> FAIL | E5: =IF(B5>=45,"PASS","FAIL") -> PASS | F5: b | G5: =AND(B5>50,C5>75) -> FALSE | H5: =IF(B5>95,"scholarship","not") -> not | I5: {=_xlfn.IFS(B5>90,"A",B5>80,"B",B5>60,"C",B5<60,"FAIL")} -> FAIL | J5: {=_xlfn.SWITCH(F5,"m","male","f","female","unknown")} -> unknown | K5: electronics | M5: {=IF(L5="",average=L3:L18,L5)} -> #VALUE! | N5: {=_xlfn.SWITCH(TRUE,B5>=85,"A",B5>=75,"B",B5>=60,"C","FAIL")} -> FAIL
B6: 76 | C6: 60 | D6: {=IF(B6>90,"A",IF(B6>75,"B",IF(B6>50,"C",FAIL)))} -> B | E6: =IF(B6>=45,"PASS","FAIL") -> PASS | F6: m | G6: =AND(B6>50,C6>75) -> FALSE | H6: =IF(B6>95,"scholarship","not") -> not | I6: {=_xlfn.IFS(B6>90,"A",B6>80,"B",B6>60,"C",B6<60,"FAIL")} -> C | J6: {=_xlfn.SWITCH(F6,"m","male","f","female","unknown")} -> male | K6: cosmetics | L6: 597 | M6: =IF(L6="",L22,L6) -> 597 | N6: {=_xlfn.SWITCH(TRUE,B6>=85,"A",B6>=75,"B",B6>=60,"C","FAIL")} -> B
B7: 79 | C7: 75 | D7: {=IF(B7>90,"A",IF(B7>75,"B",IF(B7>50,"C",FAIL)))} -> B | E7: =IF(B7>=45,"PASS","FAIL") -> PASS | F7: f | G7: =AND(B7>50,C7>75) -> FALSE | H7: =IF(B7>95,"scholarship","not") -> not | I7: {=_xlfn.IFS(B7>90,"A",B7>80,"B",B7>60,"C",B7<60,"FAIL")} -> C | J7: {=_xlfn.SWITCH(F7,"m","male","f","female","unknown")} -> female | L7: 887 | M7: =IF(L7="",L23,L7) -> 887 | N7: {=_xlfn.SWITCH(TRUE,B7>=85,"A",B7>=75,"B",B7>=60,"C","FAIL")} -> B
B8: 81 | C8: 65 | D8: {=IF(B8>90,"A",IF(B8>75,"B",IF(B8>50,"C",FAIL)))} -> B | E8: =IF(B8>=45,"PASS","FAIL") -> PASS | F8: b | G8: =AND(B8>50,C8>75) -> FALSE | H8: =IF(B8>95,"scholarship","not") -> not | I8: {=_xlfn.IFS(B8>90,"A",B8>80,"B",B8>60,"C",B8<60,"FAIL")} -> B | J8: {=_xlfn.SWITCH(F8,"m","male","f","female","unknown")} -> unknown | K8: clothes | L8: 670 | M8: =IF(L8="",L24,L8) -> 670 | N8: {=_xlfn.SWITCH(TRUE,B8>=85,"A",B8>=75,"B",B8>=60,"C","FAIL")} -> B
B9: 57 | C9: 66 | D9: {=IF(B9>90,"A",IF(B9>75,"B",IF(B9>50,"C",FAIL)))} -> C | E9: =IF(B9>=45,"PASS","FAIL") -> PASS | F9: m | G9: =AND(B9>50,C9>75) -> FALSE | H9: =IF(B9>95,"scholarship","not") -> not | I9: {=_xlfn.IFS(B9>90,"A",B9>80,"B",B9>60,"C",B9<60,"FAIL")} -> FAIL | J9: {=_xlfn.SWITCH(F9,"m","male","f","female","unknown")} -> male | K9: electronics | M9: =IF(L9="",L25,L9) -> 0 | N9: {=_xlfn.SWITCH(TRUE,B9>=85,"A",B9>=75,"B",B9>=60,"C","FAIL")} -> FAIL
B10: 72 | C10: 85 | D10: {=IF(B10>90,"A",IF(B10>75,"B",IF(B10>50,"C",FAIL)))} -> C | E10: =IF(B10>=45,"PASS","FAIL") -> PASS | F10: m | G10: =AND(B10>50,C10>75) -> TRUE | H10: =IF(B10>95,"scholarship","not") -> not | I10: {=_xlfn.IFS(B10>90,"A",B10>80,"B",B10>60,"C",B10<60,"FAIL")} -> C | J10: {=_xlfn.SWITCH(F10,"m","male","f","female","unknown")} -> male | L10: 703 | M10: =IF(L10="",L26,L10) -> 703 | N10: {=_xlfn.SWITCH(TRUE,B10>=85,"A",B10>=75,"B",B10>=60,"C","FAIL")} -> C
B11: 97 | C11: 98 | D11: {=IF(B11>90,"A",IF(B11>75,"B",IF(B11>50,"C",FAIL)))} -> A | E11: =IF(B11>=45,"PASS","FAIL") -> PASS | F11: f | G11: =AND(B11>50,C11>75) -> TRUE | H11: =IF(B11>95,"scholarship","not") -> scholarship | I11: {=_xlfn.IFS(B11>90,"A",B11>80,"B",B11>60,"C",B11<60,"FAIL")} -> A | J11: {=_xlfn.SWITCH(F11,"m","male","f","female","unknown")} -> female | K11: furniture | M11: =IF(L11="",L27,L11) -> 0 | N11: {=_xlfn.SWITCH(TRUE,B11>=85,"A",B11>=75,"B",B11>=60,"C","FAIL")} -> A
B12: 85 | C12: 79 | D12: {=IF(B12>90,"A",IF(B12>75,"B",IF(B12>50,"C",FAIL)))} -> B | E12: =IF(B12>=45,"PASS","FAIL") -> PASS | F12: f | G12: =AND(B12>50,C12>75) -> TRUE | H12: =IF(B12>95,"scholarship","not") -> not | I12: {=_xlfn.IFS(B12>90,"A",B12>80,"B",B12>60,"C",B12<60,"FAIL")} -> B | J12: {=_xlfn.SWITCH(F12,"m","male","f","female","unknown")} -> female | L12: 822 | M12: =IF(L12="",L28,L12) -> 822 | N12: {=_xlfn.SWITCH(TRUE,B12>=85,"A",B12>=75,"B",B12>=60,"C","FAIL")} -> A
B13: 47 | C13: 97 | D13: =IF(B13>90,"A",IF(B13>75,"B",IF(B13>50,"C","FAIL"))) -> FAIL | E13: =IF(B13>=45,"PASS","FAIL") -> PASS | F13: b | G13: =AND(B13>50,C13>75) -> FALSE | H13: =IF(B13>95,"scholarship","not") -> not | I13: {=_xlfn.IFS(B13>90,"A",B13>80,"B",B13>60,"C",B13<60,"FAIL")} -> FAIL | J13: {=_xlfn.SWITCH(F13,"m","male","f","female","unknown")} -> unknown | K13: cosmetics | L13: 669 | M13: =IF(L13="",L29,L13) -> 669 | N13: {=_xlfn.SWITCH(TRUE,B13>=85,"A",B13>=75,"B",B13>=60,"C","FAIL")} -> FAIL
B14: 81 | C14: 73 | D14: {=IF(B14>90,"A",IF(B14>75,"B",IF(B14>50,"C",FAIL)))} -> B | E14: =IF(B14>=45,"PASS","FAIL") -> PASS | F14: b | G14: =AND(B14>50,C14>75) -> FALSE | H14: =IF(B14>95,"scholarship","not") -> not | I14: {=_xlfn.IFS(B14>90,"A",B14>80,"B",B14>60,"C",B14<60,"FAIL")} -> B | J14: {=_xlfn.SWITCH(F14,"m","male","f","female","unknown")} -> unknown | K14: clothes | L14: 713 | M14: =IF(L14="",L30,L14) -> 713 | N14: {=_xlfn.SWITCH(TRUE,B14>=85,"A",B14>=75,"B",B14>=60,"C","FAIL")} -> B
B15: 89 | C15: 80 | D15: {=IF(B15>90,"A",IF(B15>75,"B",IF(B15>50,"C",FAIL)))} -> B | E15: =IF(B15>=45,"PASS","FAIL") -> PASS | F15: m | G15: =AND(B15>50,C15>75) -> TRUE | H15: =IF(B15>95,"scholarship","not") -> not | I15: {=_xlfn.IFS(B15>90,"A",B15>80,"B",B15>60,"C",B15<60,"FAIL")} -> B | J15: {=_xlfn.SWITCH(F15,"m","male","f","female","unknown")} -> male | K15: furniture | M15: =IF(L15="",L31,L15) -> 0 | N15: {=_xlfn.SWITCH(TRUE,B15>=85,"A",B15>=75,"B",B15>=60,"C","FAIL")} -> A
B16: 99 | C16: 66 | D16: {=IF(B16>90,"A",IF(B16>75,"B",IF(B16>50,"C",FAIL)))} -> A | E16: =IF(B16>=45,"PASS","FAIL") -> PASS | F16: m | G16: =AND(B16>50,C16>75) -> FALSE | H16: =IF(B16>95,"scholarship","not") -> scholarship | I16: {=_xlfn.IFS(B16>90,"A",B16>80,"B",B16>60,"C",B16<60,"FAIL")} -> A | J16: {=_xlfn.SWITCH(F16,"m","male","f","female","unknown")} -> male | L16: 840 | M16: =IF(L16="",L32,L16) -> 840 | N16: {=_xlfn.SWITCH(TRUE,B16>=85,"A",B16>=75,"B",B16>=60,"C","FAIL")} -> A
B17: 99 | C17: 97 | D17: {=IF(B17>90,"A",IF(B17>75,"B",IF(B17>50,"C",FAIL)))} -> A | E17: =IF(B17>=45,"PASS","FAIL") -> PASS | F17: f | G17: =AND(B17>50,C17>75) -> TRUE | H17: =IF(B17>95,"scholarship","not") -> scholarship | I17: {=_xlfn.IFS(B17>90,"A",B17>80,"B",B17>60,"C",B17<60,"FAIL")} -> A | J17: {=_xlfn.SWITCH(F17,"m","male","f","female","unknown")} -> female | K17: furniture | L17: 755 | M17: =IF(L17="",L33,L17) -> 755 | N17: {=_xlfn.SWITCH(TRUE,B17>=85,"A",B17>=75,"B",B17>=60,"C","FAIL")} -> A
B18: 55 | C18: 84 | D18: {=IF(B18>90,"A",IF(B18>75,"B",IF(B18>50,"C",FAIL)))} -> C | E18: =IF(B18>=45,"PASS","FAIL") -> PASS | F18: f | G18: =AND(B18>50,C18>75) -> TRUE | H18: =IF(B18>95,"scholarship","not") -> not | I18: {=_xlfn.IFS(B18>90,"A",B18>80,"B",B18>60,"C",B18<60,"FAIL")} -> FAIL | J18: {=_xlfn.SWITCH(F18,"m","male","f","female","unknown")} -> female | K18: clothes | L18: 553 | M18: =IF(L18="",L34,L18) -> 553 | N18: {=_xlfn.SWITCH(TRUE,B18>=85,"A",B18>=75,"B",B18>=60,"C","FAIL")} -> FAIL
L19: =AVERAGE(L3:L18) -> 709.25

Sheet excel2
A1: Discount | B1: 0.3
A2: unit_price | B2: unit | C2: total sales | D2: discount price | E2: after discount
A3: =RANDBETWEEN(1000,5000) -> 3743 | B3: =RANDBETWEEN(3,10) -> 9 | C3: =A3*B3 -> 33687 | D3: =C3*$B$1 -> 10106.1 | E3: =C3-D3 -> 23580.9
A4: =RANDBETWEEN(1000,5000) -> 4620 | B4: =RANDBETWEEN(3,10) -> 6 | C4: =A4*B4 -> 27720 | D4: =C4*$B$1 -> 8316 | E4: =C4-D4 -> 19404
A5: =RANDBETWEEN(1000,5000) -> 1432 | B5: =RANDBETWEEN(3,10) -> 9 | C5: =A5*B5 -> 12888 | D5: =C5*$B$1 -> 3866.4 | E5: =C5-D5 -> 9021.6 | P5: 7
A6: =RANDBETWEEN(1000,5000) -> 3226 | B6: =RANDBETWEEN(3,10) -> 8 | C6: =A6*B6 -> 25808 | D6: =C6*$B$1 -> 7742.4 | E6: =C6-D6 -> 18065.6 | H6: 5 | I6: 6 | J6: 7 | K6: 8 | L6: 10 | P6: 3456
A7: =RANDBETWEEN(1000,5000) -> 2994 | B7: =RANDBETWEEN(3,10) -> 3 | C7: =A7*B7 -> 8982 | D7: =C7*$B$1 -> 2694.6 | E7: =C7-D7 -> 6287.4 | G7: =RANDBETWEEN(1,10) -> 7 | H7: =$G7*H$6 -> 35 | I7: =$G7*I$6 -> 42 | J7: =$G7*J$6 -> 49 | K7: =$G7*K$6 -> 56 | L7: =$G7*L$6 -> 70 | P7: 678
A8: =RANDBETWEEN(1000,5000) -> 3236 | B8: =RANDBETWEEN(3,10) -> 7 | C8: =A8*B8 -> 22652 | D8: =C8*$B$1 -> 6795.6 | E8: =C8-D8 -> 15856.4 | G8: =RANDBETWEEN(1,10) -> 6 | H8: =$G8*H$6 -> 30 | I8: =$G8*I$6 -> 36 | J8: =$G8*J$6 -> 42 | K8: =$G8*K$6 -> 48 | L8: =$G8*L$6 -> 60 | P8: null
A9: =RANDBETWEEN(1000,5000) -> 1684 | B9: =RANDBETWEEN(3,10) -> 3 | C9: =A9*B9 -> 5052 | D9: =C9*$B$1 -> 1515.6 | E9: =C9-D9 -> 3536.4 | G9: =RANDBETWEEN(1,10) -> 3 | H9: =$G9*H$6 -> 15 | I9: =$G9*I$6 -> 18 | J9: =$G9*J$6 -> 21 | K9: =$G9*K$6 -> 24 | L9: =$G9*L$6 -> 30 | P9: excel
A10: =RANDBETWEEN(1000,5000) -> 3320 | B10: =RANDBETWEEN(3,10) -> 7 | C10: =A10*B10 -> 23240 | D10: =C10*$B$1 -> 6972 | E10: =C10-D10 -> 16268 | G10: =RANDBETWEEN(1,10) -> 9 | H10: =$G10*H$6 -> 45 | I10: =$G10*I$6 -> 54 | J10: =$G10*J$6 -> 63 | K10: =$G10*K$6 -> 72 | L10: =$G10*L$6 -> 90 | P10: 32763
A11: =RANDBETWEEN(1000,5000) -> 2792 | B11: =RANDBETWEEN(3,10) -> 3 | C11: =A11*B11 -> 8376 | D11: =C11*$B$1 -> 2512.8 | E11: =C11-D11 -> 5863.2 | G11: =RANDBETWEEN(1,10) -> 10 | H11: =$G11*H$6 -> 50 | I11: =$G11*I$6 -> 60 | J11: =$G11*J$6 -> 70 | K11: =$G11*K$6 -> 80 | L11: =$G11*L$6 -> 100 | P11: 123456
A12: =RANDBETWEEN(1000,5000) -> 2401 | B12: =RANDBETWEEN(3,10) -> 3 | C12: =A12*B12 -> 7203 | D12: =C12*$B$1 -> 2160.9 | E12: =C12-D12 -> 5042.1 | G12: =RANDBETWEEN(1,10) -> 10 | H12: =$G12*H$6 -> 50 | I12: =$G12*I$6 -> 60 | J12: =$G12*J$6 -> 70 | K12: =$G12*K$6 -> 80 | L12: =$G12*L$6 -> 100 | P12: 76
A13: =RANDBETWEEN(1000,5000) -> 1718 | B13: =RANDBETWEEN(3,10) -> 8 | C13: =A13*B13 -> 13744 | D13: =C13*$B$1 -> 4123.2 | E13: =C13-D13 -> 9620.8 | G13: =RANDBETWEEN(1,10) -> 4 | H13: =$G13*H$6 -> 20 | I13: =$G13*I$6 -> 24 | J13: =$G13*J$6 -> 28 | K13: =$G13*K$6 -> 32 | L13: =$G13*L$6 -> 40 | P13: 0
A14: =RANDBETWEEN(1000,5000) -> 2831 | B14: =RANDBETWEEN(3,10) -> 8 | C14: =A14*B14 -> 22648 | D14: =C14*$B$1 -> 6794.4 | E14: =C14-D14 -> 15853.6 | G14: =RANDBETWEEN(1,10) -> 3 | H14: =$G14*H$6 -> 15 | I14: =$G14*I$6 -> 18 | J14: =$G14*J$6 -> 21 | K14: =$G14*K$6 -> 24 | L14: =$G14*L$6 -> 30 | P14: 98
A15: =RANDBETWEEN(1000,5000) -> 2590 | B15: =RANDBETWEEN(3,10) -> 3 | C15: =A15*B15 -> 7770 | D15: =C15*$B$1 -> 2331 | E15: =C15-D15 -> 5439 | G15: =RANDBETWEEN(1,10) -> 8 | H15: =$G15*H$6 -> 40 | I15: =$G15*I$6 -> 48 | J15: =$G15*J$6 -> 56 | K15: =$G15*K$6 -> 64 | L15: =$G15*L$6 -> 80 | P15: 1
A16: =RANDBETWEEN(1000,5000) -> 4001 | B16: =RANDBETWEEN(3,10) -> 7 | C16: =A16*B16 -> 28007 | D16: =C16*$B$1 -> 8402.1 | E16: =C16-D16 -> 19604.9 | G16: =RANDBETWEEN(1,10) -> 9 | H16: =$G16*H$6 -> 45 | I16: =$G16*I$6 -> 54 | J16: =$G16*J$6 -> 63 | K16: =$G16*K$6 -> 72 | L16: =$G16*L$6 -> 90 | O16: Aggregate func
A17: =RANDBETWEEN(1000,5000) -> 1657 | B17: =RANDBETWEEN(3,10) -> 10 | C17: =A17*B17 -> 16570 | D17: =C17*$B$1 -> 4971 | E17: =C17-D17 -> 11599 | O17: sum | P17: =SUM(P5:P15) -> 160535
A18: =RANDBETWEEN(1000,5000) -> 3014 | B18: =RANDBETWEEN(3,10) -> 8 | C18: =A18*B18 -> 24112 | D18: =C18*$B$1 -> 7233.6 | E18: =C18-D18 -> 16878.4 | O18: count | P18: =COUNT(P5:P15) -> 9
A19: =RANDBETWEEN(1000,5000) -> 2704 | B19: =RANDBETWEEN(3,10) -> 5 | C19: =A19*B19 -> 13520 | D19: =C19*$B$1 -> 4056 | E19: =C19-D19 -> 9464 | O19: counta | P19: =COUNTA(P5:P15) -> 11
O20: countblank | P20: =COUNTBLANK(P5:P15) -> 0
O21: average | P21: =AVERAGE(P5:P15) -> 17837.222
O22: min | P22: =MIN(P5:P15) -> 0
O23: max | P23: =MAX(P5:P15) -> 123456
O24: mod | P24: =MOD(9,7) -> 2
O25: power | P25: =POWER(6,100) -> 6.5331862e+77
O26: abs | P26: =ABS(P18) -> 9
O27: round | P27: =ROUND(P21,3) -> 17837.222
O28: roundup | P28: =ROUNDUP(P21,1) -> 17837.3

Sheet excel 3
B4: Column1 | C4: Sales_am | D4: profit_am | E4: discount_am
B5: sum | C5: =SUM(sales_am) -> 78525755 | D5: =SUM(profit_am) -> 6872139.8 | E5: =SUM(discount_am) -> 3842.83
B6: average | C6: =AVERAGE(sales_am) -> 5117.0178 | D6: =AVERAGE(profit_am) -> 447.84228 | E6: =AVERAGE(discount_am) -> 0.2504288
B7: counta | C7: =COUNTA(sales) -> 15345 | D7: =COUNTA(profit_am) -> 15346 | E7: =COUNTA(discount_am) -> 15346

Sheet 2023
B3: Column1 | C3: jan | D3: feb | E3: mar | F3: april
B4: person a | C4: =RANDBETWEEN(100,1000) -> 526 | D4: =RANDBETWEEN(100,1000) -> 117 | E4: =RANDBETWEEN(100,1000) -> 493 | F4: =RANDBETWEEN(100,1000) -> 360
B5: person b | C5: =RANDBETWEEN(100,1000) -> 120 | D5: =RANDBETWEEN(100,1000) -> 701 | E5: =RANDBETWEEN(100,1000) -> 296 | F5: =RANDBETWEEN(100,1000) -> 568
B6: person c | C6: =RANDBETWEEN(100,1000) -> 474 | D6: =RANDBETWEEN(100,1000) -> 114 | E6: =RANDBETWEEN(100,1000) -> 690 | F6: =RANDBETWEEN(100,1000) -> 192
B7: person d | C7: =RANDBETWEEN(100,1000) -> 201 | D7: =RANDBETWEEN(100,1000) -> 500 | E7: =RANDBETWEEN(100,1000) -> 804 | F7: =RANDBETWEEN(100,1000) -> 600

Sheet 2024
B3: Column1 | C3: jan | D3: feb | E3: mar | F3: april
B4: person a | C4: =RANDBETWEEN(100,1000) -> 296 | D4: =RANDBETWEEN(100,1000) -> 248 | E4: =RANDBETWEEN(100,1000) -> 571 | F4: =RANDBETWEEN(100,1000) -> 254
B5: person b | C5: =RANDBETWEEN(100,1000) -> 656 | D5: =RANDBETWEEN(100,1000) -> 330 | E5: =RANDBETWEEN(100,1000) -> 525 | F5: =RANDBETWEEN(100,1000) -> 787
B6: person c | C6: =RANDBETWEEN(100,1000) -> 780 | D6: =RANDBETWEEN(100,1000) -> 136 | E6: =RANDBETWEEN(100,1000) -> 236 | F6: =RANDBETWEEN(100,1000) -> 441
B7: person d | C7: =RANDBETWEEN(100,1000) -> 210 | D7: =RANDBETWEEN(100,1000) -> 962 | E7: =RANDBETWEEN(100,1000) -> 545 | F7: =RANDBETWEEN(100,1000) -> 162

Sheet 2025
B3: Column1 | C3: jan | D3: feb | E3: mar | F3: april
B4: person a | C4: =RANDBETWEEN(100,1000) -> 629 | D4: =RANDBETWEEN(100,1000) -> 270 | E4: =RANDBETWEEN(100,1000) -> 948 | F4: =RANDBETWEEN(100,1000) -> 229
B5: person b | C5: =RANDBETWEEN(100,1000) -> 445 | D5: =RANDBETWEEN(100,1000) -> 791 | E5: =RANDBETWEEN(100,1000) -> 736 | F5: =RANDBETWEEN(100,1000) -> 768
B6: person c | C6: =RANDBETWEEN(100,1000) -> 658 | D6: =RANDBETWEEN(100,1000) -> 252 | E6: =RANDBETWEEN(100,1000) -> 662 | F6: =RANDBETWEEN(100,1000) -> 535
B7: person d | C7: =RANDBETWEEN(100,1000) -> 630 | D7: =RANDBETWEEN(100,1000) -> 374 | E7: =RANDBETWEEN(100,1000) -> 189 | F7: =RANDBETWEEN(100,1000) -> 154

Sheet consolidation
B3: Column1 | C3: jan | D3: feb | E3: mar | F3: april | H3: Column1 | I3: jan | J3: feb | K3: mar | L3: april
B4: person a | C4: =SUM('2023:2025'!C4) -> 1451 | D4: =SUM('2023:2025'!D4) -> 635 | E4: =SUM('2023:2025'!E4) -> 2012 | F4: =SUM('2023:2025'!F4) -> 843 | H4: person a | I4: =SUM('2023:2025'!I4) -> 0 | J4: =SUM('2023:2025'!J4) -> 0 | K4: =SUM('2023:2025'!K4) -> 0 | L4: =SUM('2023:2025'!L4) -> 0
B5: person b | C5: =SUM('2023:2025'!C5) -> 1221 | D5: =SUM('2023:2025'!D5) -> 1822 | E5: =SUM('2023:2025'!E5) -> 1557 | F5: =SUM('2023:2025'!F5) -> 2123 | H5: person b | I5: =SUM('2023:2025'!I5) -> 0 | J5: =SUM('2023:2025'!J5) -> 0 | K5: =SUM('2023:2025'!K5) -> 0 | L5: =SUM('2023:2025'!L5) -> 0
B6: person c | C6: =SUM('2023:2025'!C6) -> 1912 | D6: =SUM('2023:2025'!D6) -> 502 | E6: =SUM('2023:2025'!E6) -> 1588 | F6: =SUM('2023:2025'!F6) -> 1168 | H6: person c | I6: =SUM('2023:2025'!I6) -> 0 | J6: =SUM('2023:2025'!J6) -> 0 | K6: =SUM('2023:2025'!K6) -> 0 | L6: =SUM('2023:2025'!L6) -> 0
B7: person d | C7: =SUM('2023:2025'!C7) -> 1041 | D7: =SUM('2023:2025'!D7) -> 1836 | E7: =SUM('2023:2025'!E7) -> 1538 | F7: =SUM('2023:2025'!F7) -> 916 | H7: person d | I7: =SUM('2023:2025'!I7) -> 0 | J7: =SUM('2023:2025'!J7) -> 0 | K7: =SUM('2023:2025'!K7) -> 0 | L7: =SUM('2023:2025'!L7) -> 0
E10: jan | F10: feb | G10: march | J10: jan | K10: feb | L10: march
D11: a | E11: =RANDBETWEEN(100,500) -> 218 | F11: =RANDBETWEEN(100,500) -> 320 | G11: =RANDBETWEEN(100,500) -> 120 | I11: a | J11: =RANDBETWEEN(100,500) -> 362 | K11: =RANDBETWEEN(100,500) -> 208 | L11: =RANDBETWEEN(100,500) -> 437
D12: b | E12: =RANDBETWEEN(100,500) -> 421 | F12: =RANDBETWEEN(100,500) -> 127 | G12: =RANDBETWEEN(100,500) -> 261 | I12: b | J12: =RANDBETWEEN(100,500) -> 489 | K12: =RANDBETWEEN(100,500) -> 149 | L12: =RANDBETWEEN(100,500) -> 324
D13: c | E13: =RANDBETWEEN(100,500) -> 296 | F13: =RANDBETWEEN(100,500) -> 117 | G13: =RANDBETWEEN(100,500) -> 204 | I13: c | J13: =RANDBETWEEN(100,500) -> 339 | K13: =RANDBETWEEN(100,500) -> 403 | L13: =RANDBETWEEN(100,500) -> 317

Sheet Sheet8
D2: JAN | E2: FEB | F2: MAR | G2: APR | L2: SECOND SPACE | M2: FIRST SPACE | N2: NAME | O2: FIRST NAME
C3: PERSON A | D3: =RANDBETWEEN(-1000,1000) -> 71 | E3: =RANDBETWEEN(-1000,1000) -> 597 | F3: =RANDBETWEEN(-1000,1000) -> -998 | G3: =RANDBETWEEN(-1000,1000) -> -170 | L3: =FIND(" ",N3,M3+1) -> 7 | M3: =FIND(" ",N3) -> 3 | N3: AA AAA AAAA | O3: =LEFT(N3,M3-1) -> AA
C4: PERSON B | D4: =RANDBETWEEN(-1000,1000) -> 789 | E4: =RANDBETWEEN(-1000,1000) -> -425 | F4: =RANDBETWEEN(-1000,1000) -> -186 | G4: =RANDBETWEEN(-1000,1000) -> 687 | L4: =FIND(" ",N4,M4+1) -> 5 | M4: =FIND(" ",N4) -> 2 | N4: B BB BBB | O4: =LEFT(N4,M4-1) -> B
C5: PERSON C | D5: =RANDBETWEEN(-1000,1000) -> -740 | E5: =RANDBETWEEN(-1000,1000) -> -475 | F5: =RANDBETWEEN(-1000,1000) -> -575 | G5: =RANDBETWEEN(-1000,1000) -> 926 | L5: =FIND(" ",N5,M5+1) -> 9 | M5: =FIND(" ",N5) -> 4 | N5: CCC CCCC CCCC | O5: =LEFT(N5,M5-1) -> CCC
C6: PERSON D | D6: =RANDBETWEEN(-1000,1000) -> 491 | E6: =RANDBETWEEN(-1000,1000) -> 710 | F6: =RANDBETWEEN(-1000,1000) -> 594 | G6: =RANDBETWEEN(-1000,1000) -> -737 | L6: =FIND(" ",N6,M6+1) -> 6 | M6: =FIND(" ",N6) -> 4 | N6: DDD D DD | O6: =LEFT(N6,M6-1) -> DDD
C7: PERSON E | D7: =RANDBETWEEN(-1000,1000) -> -143 | E7: =RANDBETWEEN(-1000,1000) -> 814 | F7: =RANDBETWEEN(-1000,1000) -> -586 | G7: =RANDBETWEEN(-1000,1000) -> 245
C8: PERSON F | D8: =RANDBETWEEN(-1000,1000) -> -573 | E8: =RANDBETWEEN(-1000,1000) -> -431 | F8: =RANDBETWEEN(-1000,1000) -> -283 | G8: =RANDBETWEEN(-1000,1000) -> 114
D12: FLASH FILL
D13: DUPLICATE VALUES
D14: DATA VALIDATION
D15: LIST
D17: LEFT | J17: NAME | K17: LENGTH | L17: TRIM | M17: UPPER | N17: LOWER | O17: PROPER | P17: SEARCH | Q17: CONCAT | R17: TEXT JOIN
D18: RIGHT | J18: RAHUL MISHRA | K18: =LEN(J18) -> 13 | L18: =TRIM(J18) -> RAHUL MISHRA | M18: =UPPER(J18) -> RAHUL MISHRA | N18: =LOWER(J18) -> rahul mishra | O18: =PROPER(J18) -> Rahul Mishra | P18: =SEARCH(7,J18,2) -> #VALUE! | R18: =_xlfn.TEXTJOIN(J18," ",J18,J18) -> #VALUE!
D19: MID | J19: RIYA GUPTA | K19: =LEN(J19) -> 10 | L19: =TRIM(J19) -> RIYA GUPTA | M19: =UPPER(J19) -> RIYA GUPTA | N19: =LOWER(J19) -> riya gupta | O19: =PROPER(J19) -> Riya Gupta | P19: =SEARCH(7,J19,2) -> #VALUE!
D20: LENGTH
D21: TRIM
D22: UPPER
D23: LOWER
D24: PROPER
D25: FIND
D26: SEARCH
D27: CONCAT
D28: TEXT JOIN
D29: substitur
D30: replace

Sheet 4-8
B2: orderid | C2: customer | D2: region | E2: products | F2: category | G2: quantity | H2: unit price | I2: sales | J2: payment | K2: city
B3: 4 | C3: aman | D3: north | E3: chair | F3: furniture | G3: 4660 | H3: 17145 | I3: 38387 | J3: upi | K3: chennai | M3: region wise sales | N3: sumif | O3: countif | P3: averageif | Q3: sumifs
B4: 2 | C4: ayesha | D4: east | E4: chair | F4: furniture | G4: 1244 | H4: 43947 | I4: 53860 | J4: upi | K4: mumbai | M4: north | N4: =SUMIF(D3:D12,"north",I3:I12) -> 102512 | O4: =COUNTIF(Table8[region],M4) -> 3 | P4: =AVERAGEIF(Table8[region],M4,Table8[sales]) -> 34170.667 | Q4: =SUMIFS(Table8[sales],Table8[region],M4,Table8[payment],"upi") -> 94755
B5: 8 | C5: kapil | D5: east | E5: laptop | F5: electronics | G5: 2834 | H5: 54076 | I5: 56073 | J5: card | K5: pune | M5: west | N5: =SUMIF(D4:D13,"west",I4:I13) -> 38829 | O5: =COUNTIF(Table8[region],M5) -> 3 | P5: =AVERAGEIF(Table8[region],M5,Table8[sales]) -> 12943 | Q5: =SUMIFS(Table8[sales],Table8[region],M5,Table8[payment],"upi") -> 9254
B6: 3 | C6: neel | D6: north | E6: bottle | F6: object | G6: 2862 | H6: 37740 | I6: 7757 | J6: cash | K6: hydrabad | M6: east | N6: =SUMIF(D5:D14,"east",I5:I14) -> 56073 | O6: =COUNTIF(Table8[region],M6) -> 2 | P6: =AVERAGEIF(Table8[region],M6,Table8[sales]) -> 54966.5 | Q6: =SUMIFS(Table8[sales],Table8[region],M6,Table8[payment],"upi") -> 53860
B7: 5 | C7: neha | D7: south | E7: bottle | F7: object | G7: 2757 | H7: 33420 | I7: 43212 | J7: cash | K7: chennai | M7: south | N7: =SUMIF(D6:D15,"south",I6:I15) -> 101791 | O7: =COUNTIF(Table8[region],M7) -> 2 | P7: =AVERAGEIF(Table8[region],M7,Table8[sales]) -> 50895.5 | Q7: =SUMIFS(Table8[sales],Table8[region],M7,Table8[payment],"upi") -> 58579
B8: 7 | C8: pooja | D8: west | E8: laptop | F8: electronics | G8: 4225 | H8: 7560 | I8: 26350 | J8: card | K8: hydrabad
B9: 1 | C9: rahul | D9: west | E9: laptop | F9: electronics | G9: 2316 | H9: 39203 | I9: 9254 | J9: upi | K9: pune | M9: index func | N9: =INDEX(Table8[orderid],3) -> 8 | O9: =INDEX(Table8[],9,5) -> object | R9: kapil | S9: sales
B10: 9 | C10: ram | D10: north | E10: laptop | F10: electronics | G10: 2915 | H10: 21924 | I10: 56368 | J10: upi | K10: mumbai | M10: math func | N10: =MATCH("pooja",Table8[[#All],[customer]],0) -> 7 | O10: =MATCH("quantity",Table8[#Headers],0) -> 6 | R10: =MATCH(R9,C2:C12,0) -> 4 | S10: =MATCH(S9,Table8[#Headers],0) -> 8
B11: 6 | C11: riya | D11: west | E11: bottle | F11: object | G11: 2021 | H11: 28562 | I11: 3225 | J11: cash | K11: mumbai
B12: 10 | C12: rohan | D12: south | E12: chair | F12: furniture | G12: 3385 | H12: 13663 | I12: 58579 | J12: upi | K12: mumbai | Q12: sales | R12: region | S12: quantity | T12: payment
P13: kapil | Q13: {=INDEX(Table8[#All],R10,S10)} -> 56073
P14: neha | Q14: {=INDEX(Table8[#All],P14,S9)} -> #VALUE!
P15: neel
P16: pooja

Sheet 5-8
A1: orderid | B1: customer | C1: region | D1: products | E1: category | F1: quantity | G1: unit price | H1: sales | I1: payment | J1: city | M1: LOOKUP
A2: 4 | B2: aman | C2: north | D2: chair | E2: furniture | F2: 4660 | G2: 17145 | H2: 38387 | I2: upi | J2: chennai | M2: neha | N2: pooja | O2: ram
A3: 2 | B3: ayesha | C3: east | D3: chair | E3: furniture | F3: 1244 | G3: 43947 | H3: 53860 | I3: upi | J3: mumbai | M3: =LOOKUP(M2,B2:B11,D2:D11) -> bottle | N3: =LOOKUP(N2,B2:B11,I2:I11) -> card | O3: =LOOKUP(O2,B2:B11,J2:J11) -> mumbai
A4: 8 | B4: kapil | C4: east | D4: laptop | E4: electronics | F4: 2834 | G4: 54076 | H4: 56073 | I4: card | J4: pune
A5: 3 | B5: neel | C5: north | D5: bottle | E5: object | F5: 2862 | G5: 37740 | H5: 7757 | I5: cash | J5: hydrabad | M5: VLOOKUP
A6: 5 | B6: neha | C6: south | D6: bottle | E6: object | F6: 2757 | G6: 33420 | H6: 43212 | I6: cash | J6: chennai | M6: neel | O6: withouth match
A7: 7 | B7: pooja | C7: west | D7: laptop | E7: electronics | F7: 4225 | G7: 7560 | H7: 26350 | I7: card | J7: hydrabad | M7: =VLOOKUP(M6,B1:J11,6,FALSE) -> 37740
A8: 1 | B8: rahul | C8: west | D8: laptop | E8: electronics | F8: 2316 | G8: 39203 | H8: 9254 | I8: upi | J8: pune | N8: payment | P8: with match
A9: 9 | B9: ram | C9: north | D9: laptop | E9: electronics | F9: 2915 | G9: 21924 | H9: 56368 | I9: upi | J9: mumbai | M9: pooja | N9: =VLOOKUP(M9,B1:J11,MATCH(N8,B1:J1,0),FALSE) -> card
A10: 6 | B10: riya | C10: west | D10: bottle | E10: object | F10: 2021 | G10: 28562 | H10: 3225 | I10: cash | J10: mumbai
A11: 10 | B11: rohan | C11: south | D11: chair | E11: furniture | F11: 3385 | G11: 13663 | H11: 58579 | I11: upi | J11: mumbai | M11: HLOOKUP
M12: ID | N12: 1 | O12: 2 | P12: 3 | Q12: 4 | R12: 5 | S12: 6
A13: XLOOKUP | M13: Name | N13: Person A | O13: Person B | P13: Person C | Q13: Person D | R13: Person E | S13: Person F
A14: pooja | M14: Department | N14: IT | O14: Sales | P14: Finance | Q14: IT | R14: Sales | S14: Finance
A15: =_xlfn.XLOOKUP(A14,B1:B11,J1:J11,"-",0,1) -> hydrabad | M15: Salary | N15: 56622 | O15: 58377 | P15: 62217 | Q15: 54271 | R15: 54258 | S15: 51466
M16: city | N16: Kalyan | O16: Thane | P16: Dombivli | Q16: Powai | R16: Andheri | S16: Dadar
M18: IT
M19: =HLOOKUP(M18,N14:S16,3,FALSE) -> Kalyan

Sheet vlookup
A1: Order_Id | B1: Sales | C1: Profit | D1: City
A2: ORD100000 | B2: VLOOKUP | C2: {=_xlfn.XLOOKUP(A2,Table2[[#Headers],[#Data],[order_id]],Table2[[#Headers],[#Data],[profit]],"-",0,1)} -> 114.72 | D2: =INDEX(Table2[[#Headers],[#Data]],MATCH(vlookup!A2,Table2[[#Headers],[#Data],[order_id]],0),MATCH(vlookup!$D$1,Table2[#Headers],0)) -> Pune
A3: ORD100009 | C3: {=_xlfn.XLOOKUP(A3,Table2[[#Headers],[#Data],[order_id]],Table2[[#Headers],[#Data],[profit]],"-",0,1)} -> 102.96 | D3: =INDEX(Table2[[#Headers],[#Data]],MATCH(vlookup!A3,Table2[[#Headers],[#Data],[order_id]],0),MATCH(vlookup!$D$1,Table2[#Headers],0)) -> Pune
A4: ORD100018 | C4: {=_xlfn.XLOOKUP(A4,Table2[[#Headers],[#Data],[order_id]],Table2[[#Headers],[#Data],[profit]],"-",0,1)} -> 260.95 | D4: =INDEX(Table2[[#Headers],[#Data]],MATCH(vlookup!A4,Table2[[#Headers],[#Data],[order_id]],0),MATCH(vlookup!$D$1,Table2[#Headers],0)) -> Bangalore
A5: ORD100027 | C5: {=_xlfn.XLOOKUP(A5,Table2[[#Headers],[#Data],[order_id]],Table2[[#Headers],[#Data],[profit]],"-",0,1)} -> 689.74 | D5: =INDEX(Table2[[#Headers],[#Data]],MATCH(vlookup!A5,Table2[[#Headers],[#Data],[order_id]],0),MATCH(vlookup!$D$1,Table2[#Headers],0)) -> Mumbai
A6: ORD100036 | C6: {=_xlfn.XLOOKUP(A6,Table2[[#Headers],[#Data],[order_id]],Table2[[#Headers],[#Data],[profit]],"-",0,1)} -> 528.38 | D6: =INDEX(Table2[[#Headers],[#Data]],MATCH(vlookup!A6,Table2[[#Headers],[#Data],[order_id]],0),MATCH(vlookup!$D$1,Table2[#Headers],0)) -> Chennai
A7: ORD100045 | C7: {=_xlfn.XLOOKUP(A7,Table2[[#Headers],[#Data],[order_id]],Table2[[#Headers],[#Data],[profit]],"-",0,1)} -> 588.79 | D7: =INDEX(Table2[[#Headers],[#Data]],MATCH(vlookup!A7,Table2[[#Headers],[#Data],[order_id]],0),MATCH(vlookup!$D$1,Table2[#Headers],0)) -> Chennai
A8: ORD100054 | C8: {=_xlfn.XLOOKUP(A8,Table2[[#Headers],[#Data],[order_id]],Table2[[#Headers],[#Data],[profit]],"-",0,1)} -> 237.01 | D8: =INDEX(Table2[[#Headers],[#Data]],MATCH(vlookup!A8,Table2[[#Headers],[#Data],[order_id]],0),MATCH(vlookup!$D$1,Table2[#Headers],0)) -> Delhi
A9: ORD100063 | C9: {=_xlfn.XLOOKUP(A9,Table2[[#Headers],[#Data],[order_id]],Table2[[#Headers],[#Data],[profit]],"-",0,1)} -> 36.86 | D9: =INDEX(Table2[[#Headers],[#Data]],MATCH(vlookup!A9,Table2[[#Headers],[#Data],[order_id]],0),MATCH(vlookup!$D$1,Table2[#Headers],0)) -> Mumbai
A10: ORD100072 | C10: {=_xlfn.XLOOKUP(A10,Table2[[#Headers],[#Data],[order_id]],Table2[[#Headers],[#Data],[profit]],"-",0,1)} -> 1229.3 | D10: =INDEX(Table2[[#Headers],[#Data]],MATCH(vlookup!A10,Table2[[#Headers],[#Data],[order_id]],0),MATCH(vlookup!$D$1,Table2[#Headers],0)) -> Chennai
A11: ORD100081 | C11: {=_xlfn.XLOOKUP(A11,Table2[[#Headers],[#Data],[order_id]],Table2[[#Headers],[#Data],[profit]],"-",0,1)} -> 175.75 | D11: =INDEX(Table2[[#Headers],[#Data]],MATCH(vlookup!A11,Table2[[#Headers],[#Data],[order_id]],0),MATCH(vlookup!$D$1,Table2[#Headers],0)) -> Hyderabad
A12: ORD100090 | C12: {=_xlfn.XLOOKUP(A12,Table2[[#Headers],[#Data],[order_id]],Table2[[#Headers],[#Data],[profit]],"-",0,1)} -> 1325.93 | D12: =INDEX(Table2[[#Headers],[#Data]],MATCH(vlookup!A12,Table2[[#Headers],[#Data],[order_id]],0),MATCH(vlookup!$D$1,Table2[#Headers],0)) -> Mumbai
A13: ORD100099 | C13: {=_xlfn.XLOOKUP(A13,Table2[[#Headers],[#Data],[order_id]],Table2[[#Headers],[#Data],[profit]],"-",0,1)} -> 186.24 | D13: =INDEX(Table2[[#Headers],[#Data]],MATCH(vlookup!A13,Table2[[#Headers],[#Data],[order_id]],0),MATCH(vlookup!$D$1,Table2[#Headers],0)) -> Hyderabad
A14: ORD100108 | C14: {=_xlfn.XLOOKUP(A14,Table2[[#Headers],[#Data],[order_id]],Table2[[#Headers],[#Data],[profit]],"-",0,1)} -> 1092.43 | D14: =INDEX(Table2[[#Headers],[#Data]],MATCH(vlookup!A14,Table2[[#Headers],[#Data],[order_id]],0),MATCH(vlookup!$D$1,Table2[#Headers],0)) -> Pune
... A481: ORD104311 | C481: {=_xlfn.XLOOKUP(A481,Table2[[#Headers],[#Data],[order_id]],Table2[[#Headers],[#Data],[profit]],"-",0,1)} -> 95.98 | D481: =INDEX(Table2[[#Headers],[#Data]],MATCH(vlookup!A481,Table2[[#Headers],[#Data],[order_id]],0),MATCH(vlookup!$D$1,Table2[#Headers],0)) -> Pune
